Workbook

Sheet users
A1: user_id | B1: fullname | C1: gender | D1: age | E1: department
A2: =ROW()-1 -> 1 | B2: HAFIZHAN SHIDQI | C2: male | D2: 22 | E2: Akuntansi
A3: =ROW()-1 -> 2 | B3: GANDHI WIBOWO | C3: male | D3: 45 | E3: Risk Management
A4: =ROW()-1 -> 3 | B4: ALDIO MAHENDRA PURWANDRARTO | C4: male | D4: 48 | E4: Legal & Compliance
A5: =ROW()-1 -> 4 | B5: BENNY PUTRA | C5: male | D5: 24 | E5: Penjualan
A6: =ROW()-1 -> 5 | B6: VICKY VERNANDO DASTA | C6: male | D6: 40 | E6: SDM
A7: =ROW()-1 -> 6 | B7: JUFIANTO HENRI | C7: male | D7: 45 | E7: SDM
A8: =ROW()-1 -> 7 | B8: AAN NURAINI | C8: female | D8: 22 | E8: HSE
A9: =ROW()-1 -> 8 | B9: ABDUR RAHMAN | C9: male | D9: 54 | E9: Business Development
A10: =ROW()-1 -> 9 | B10: ABDURRAHMAN | C10: male | D10: 35 | E10: SDM
A11: =ROW()-1 -> 10 | B11: ADE INDRA SUKMA | C11: female | D11: 31 | E11: HSE
A12: =ROW()-1 -> 11 | B12: ADE IRMAYANI | C12: female | D12: 50 | E12: Penjualan
A13: =ROW()-1 -> 12 | B13: BAKTI YOGA FIYANDANA | C13: male | D13: 41 | E13: Strategic Planning
... A1960: =ROW()-1 -> 1959 | B1960: SUKANDI | C1960: male | D1960: 36 | E1960: Penjualan

Sheet activity_logs
A1: activity_id | B1: user_id | C1: average_speed | D1: max_speed | E1: average_heartrate | F1: max_heartrate | G1: distance | H1: elapsed_time | I1: moving_time | J1: total_elevation_gain | K1: elev_high | L1: type | M1: start_date_local | N1: kudos_count
A2: =row()-1 -> 1 | B2: {=INDEX(users!$A:$A, RANDBETWEEN(1, COUNTA(users!$A:$A)))} -> 1242 | C2: 2.284 | D2: 5.5 | G2: 11250 | H2: 0.064861111 | I2: 0.057013889 | J2: 166 | K2: 958.8 | L2: Run | M2: 45292.501 | N2: 0
A3: =row()-1 -> 2 | B3: {=INDEX(users!$A:$A, RANDBETWEEN(1, COUNTA(users!$A:$A)))} -> 1432 | C3: 2.927 | D3: 3.5 | G3: 4112 | H3: 0.023043981 | I3: 0.016261574 | J3: 9 | K3: 329.8 | L3: Run | M3: 45295.796 | N3: 4
A4: =row()-1 -> 3 | B4: {=INDEX(users!$A:$A, RANDBETWEEN(1, COUNTA(users!$A:$A)))} -> 189 | C4: 2.845 | D4: 4.2 | G4: 4524.1 | H4: 0.021099537 | I4: 0.018402778 | J4: 65 | K4: 83.6 | L4: Run | M4: 45297.539 | N4: 1
A5: =row()-1 -> 4 | B5: {=INDEX(users!$A:$A, RANDBETWEEN(1, COUNTA(users!$A:$A)))} -> 1785 | C5: 2.872 | D5: 3.9 | G5: 5842.6 | H5: 0.026284722 | I5: 0.023541667 | J5: 92 | K5: 147.8 | L5: Run | M5: 45298.547 | N5: 3
A6: =row()-1 -> 5 | B6: {=INDEX(users!$A:$A, RANDBETWEEN(1, COUNTA(users!$A:$A)))} -> 1795 | C6: 2.844 | D6: 5 | G6: 6958.7 | H6: 0.030208333 | I6: 0.028321759 | J6: 100 | K6: 137.6 | L6: Run | M6: 45300.463 | N6: 3
A7: =row()-1 -> 6 | B7: {=INDEX(users!$A:$A, RANDBETWEEN(1, COUNTA(users!$A:$A)))} -> 1145 | C7: 2.29 | D7: 3.8 | G7: 916 | H7: 0.02056713 | I7: 0.0046296296 | J7: 6 | K7: 101 | L7: Run | M7: 45302.755 | N7: 4
A8: =row()-1 -> 7 | B8: {=INDEX(users!$A:$A, RANDBETWEEN(1, COUNTA(users!$A:$A)))} -> 735 | C8: 2.315 | D8: 3.8 | G8: 6018.5 | H8: 0.031053241 | I8: 0.030092593 | J8: 41 | K8: 96 | L8: Run | M8: 45302.82 | N8: 7
A9: =row()-1 -> 8 | B9: {=INDEX(users!$A:$A, RANDBETWEEN(1, COUNTA(users!$A:$A)))} -> 1491 | C9: 2.756 | D9: 4 | E9: 140.5 | F9: 151 | G9: 5631.4 | H9: 0.04400463 | I9: 0.023645833 | J9: 32 | K9: 144.2 | L9: Run | M9: 45304.497 | N9: 6
A10: =row()-1 -> 9 | B10: {=INDEX(users!$A:$A, RANDBETWEEN(1, COUNTA(users!$A:$A)))} -> 1459 | C10: 2.053 | D10: 4.7 | G10: 2930 | H10: 0.019895833 | I10: 0.016516204 | J10: 18 | K10: 133.2 | L10: Run | M10: 45305.773 | N10: 7
A11: =row()-1 -> 10 | B11: {=INDEX(users!$A:$A, RANDBETWEEN(1, COUNTA(users!$A:$A)))} -> 805 | C11: 3.101 | D11: 4.3 | G11: 6056.6 | H11: 0.024236111 | I11: 0.022604167 | J11: 16 | K11: 50.2 | L11: Run | M11: 45307.634 | N11: 5
A12: =row()-1 -> 11 | B12: {=INDEX(users!$A:$A, RANDBETWEEN(1, COUNTA(users!$A:$A)))} -> 1823 | C12: 0.978 | D12: 3.3 | G12: 442 | H12: 0.028449074 | I12: 0.0052314815 | J12: 0 | K12: -154.2 | L12: Run | M12: 45308.739 | N12: 0
A13: =row()-1 -> 12 | B13: {=INDEX(users!$A:$A, RANDBETWEEN(1, COUNTA(users!$A:$A)))} -> 601 | C13: 2.449 | D13: 4.1 | G13: 7679.5 | H13: 0.038784722 | I13: 0.036296296 | J13: 100 | K13: 130 | L13: Run | M13: 45309.793 | N13: 4
A14: =row()-1 -> 13 | B14: {=INDEX(users!$A:$A, RANDBETWEEN(1, COUNTA(users!$A:$A)))} -> 887 | C14: 2.555 | D14: 4 | E14: 140.6 | F14: 165 | G14: 5565.8 | H14: 0.035439815 | I14: 0.025208333 | J14: 120 | K14: 119.2 | L14: Run | M14: 45312.439 | N14: 4
A15: =row()-1 -> 14 | B15: {=INDEX(users!$A:$A, RANDBETWEEN(1, COUNTA(users!$A:$A)))} -> 24 | C15: 0.557 | D15: 1.2 | G15: 1000 | H15: 0.021979167 | I15: 0.020787037 | J15: 0 | L15: Swim | M15: 45313.353 | N15: 3
A16: =row()-1 -> 15 | B16: {=INDEX(users!$A:$A, RANDBETWEEN(1, COUNTA(users!$A:$A)))} -> 827 | C16: 2.902 | D16: 5.1 | E16: 139.3 | F16: 158 | G16: 4201.8 | H16: 0.028819444 | I16: 0.016759259 | J16: 20 | K16: 96.6 | L16: Run | M16: 45313.529 | N16: 7
A17: =row()-1 -> 16 | B17: {=INDEX(users!$A:$A, RANDBETWEEN(1, COUNTA(users!$A:$A)))} -> 1656 | C17: 0.671 | D17: 1.5 | G17: 1725 | H17: 0.030486111 | I17: 0.029768519 | J17: 0 | L17: Swim | M17: 45314.581 | N17: 6
A18: =row()-1 -> 17 | B18: {=INDEX(users!$A:$A, RANDBETWEEN(1, COUNTA(users!$A:$A)))} -> 1491 | C18: 1.288 | D18: 2.4 | G18: 793.5 | H18: 0.011527778 | I18: 0.0071296296 | J18: 1 | K18: 153.8 | L18: Run | M18: 45315.737 | N18: 2
A19: =row()-1 -> 18 | B19: {=INDEX(users!$A:$A, RANDBETWEEN(1, COUNTA(users!$A:$A)))} -> 1047 | C19: 0.581 | D19: 0.8 | G19: 925 | H19: 0.019386574 | I19: 0.018425926 | J19: 0 | L19: Swim | M19: 45316.561 | N19: 8
A20: =row()-1 -> 19 | B20: {=INDEX(users!$A:$A, RANDBETWEEN(1, COUNTA(users!$A:$A)))} -> 256 | C20: 1.937 | D20: 5.4 | E20: 137.6 | F20: 174 | G20: 4622.8 | H20: 0.0365625 | I20: 0.027627315 | J20: 206 | K20: 130.2 | L20: Run | M20: 45316.794 | N20: 9
A21: =row()-1 -> 20 | B21: {=INDEX(users!$A:$A, RANDBETWEEN(1, COUNTA(users!$A:$A)))} -> 828 | C21: 1.194 | D21: 3.2 | G21: 2766.2 | H21: 0.043425926 | I21: 0.026805556 | J21: 7 | K21: 106.8 | L21: Run | M21: 45317.73 | N21: 4
A22: =row()-1 -> 21 | B22: {=INDEX(users!$A:$A, RANDBETWEEN(1, COUNTA(users!$A:$A)))} -> 1067 | C22: 0.624 | D22: 1.2 | G22: 1125 | H22: 0.021469907 | I22: 0.02087963 | J22: 0 | L22: Swim | M22: 45318.513 | N22: 8
A23: =row()-1 -> 22 | B23: {=INDEX(users!$A:$A, RANDBETWEEN(1, COUNTA(users!$A:$A)))} -> 887 | C23: 2.857 | D23: 3.6 | E23: 133.8 | F23: 145 | G23: 1902.5 | H23: 0.017083333 | I23: 0.0077083333 | J23: 8 | K23: 90.2 | L23: Run | M23: 45319.439 | N23: 4
A24: =row()-1 -> 23 | B24: {=INDEX(users!$A:$A, RANDBETWEEN(1, COUNTA(users!$A:$A)))} -> 1059 | C24: 3.233 | D24: 5 | E24: 141.3 | F24: 174 | G24: 9342 | H24: 0.033449074 | I24: 0.033449074 | J24: 239 | K24: 109 | L24: Run | M24: 45319.458 | N24: 5
A25: =row()-1 -> 24 | B25: {=INDEX(users!$A:$A, RANDBETWEEN(1, COUNTA(users!$A:$A)))} -> 1844 | C25: 0.692 | D25: 0.9 | G25: 1000 | H25: 0.019305556 | I25: 0.016724537 | J25: 0 | L25: Swim | M25: 45321.55 | N25: 7
A26: =row()-1 -> 25 | B26: {=INDEX(users!$A:$A, RANDBETWEEN(1, COUNTA(users!$A:$A)))} -> 339 | C26: 1.682 | D26: 3.4 | G26: 1977.5 | H26: 0.028993056 | I26: 0.013611111 | J26: 1 | K26: 141.2 | L26: Run | M26: 45322.739 | N26: 0
A27: =row()-1 -> 26 | B27: {=INDEX(users!$A:$A, RANDBETWEEN(1, COUNTA(users!$A:$A)))} -> 1786 | C27: 2.547 | D27: 6.8 | G27: 5139.4 | H27: 0.033194444 | I27: 0.023356481 | J27: 22 | K27: 137.6 | L27: Run | M27: 45323.793 | N27: 4
A28: =row()-1 -> 27 | B28: {=INDEX(users!$A:$A, RANDBETWEEN(1, COUNTA(users!$A:$A)))} -> 1666 | C28: 0.594 | D28: 0.9 | G28: 925 | H28: 0.018668981 | I28: 0.018032407 | J28: 0 | L28: Swim | M28: 45324.548 | N28: 5
A29: =row()-1 -> 28 | B29: {=INDEX(users!$A:$A, RANDBETWEEN(1, COUNTA(users!$A:$A)))} -> 1788 | C29: 3.309 | D29: 6.1 | G29: 10985.9 | H29: 0.04400463 | I29: 0.038425926 | J29: 14.7 | K29: 112 | L29: Run | M29: 45324.603 | N29: 0
A30: =row()-1 -> 29 | B30: {=INDEX(users!$A:$A, RANDBETWEEN(1, COUNTA(users!$A:$A)))} -> 1574 | C30: 1.453 | D30: 2.3 | G30: 1406.6 | H30: 0.046388889 | I30: 0.011203704 | J30: 0 | K30: 192.6 | L30: Run | M30: 45324.729 | N30: 0
A31: =row()-1 -> 30 | B31: {=INDEX(users!$A:$A, RANDBETWEEN(1, COUNTA(users!$A:$A)))} -> 1917 | C31: 3.679 | D31: 7.2 | G31: 16433.1 | H31: 0.056539352 | I31: 0.051701389 | J31: 56.8 | K31: 120.7 | L31: Run | M31: 45325.315 | N31: 0
A32: =row()-1 -> 31 | B32: {=INDEX(users!$A:$A, RANDBETWEEN(1, COUNTA(users!$A:$A)))} -> 911 | C32: 3.046 | D32: 4.2 | G32: 3493.4 | H32: 0.020243056 | I32: 0.013275463 | J32: 11 | K32: 233.6 | L32: Run | M32: 45326.513 | N32: 4
A33: =row()-1 -> 32 | B33: {=INDEX(users!$A:$A, RANDBETWEEN(1, COUNTA(users!$A:$A)))} -> 455 | C33: 3.163 | D33: 3.6 | G33: 667.4 | H33: 0.0024884259 | I33: 0.0024421296 | J33: 1 | K33: 234.4 | L33: Run | M33: 45326.545 | N33: 4
A34: =row()-1 -> 33 | B34: {=INDEX(users!$A:$A, RANDBETWEEN(1, COUNTA(users!$A:$A)))} -> 611 | C34: 1.937 | D34: 4.6 | G34: 5875.9 | H34: 0.042662037 | I34: 0.035104167 | J34: 40 | K34: 105.8 | L34: Run | M34: 45327.47 | N34: 6
A35: =row()-1 -> 34 | B35: {=INDEX(users!$A:$A, RANDBETWEEN(1, COUNTA(users!$A:$A)))} -> 1083 | C35: 0.664 | D35: 1.5 | G35: 2050 | H35: 0.040138889 | I35: 0.035729167 | J35: 0 | L35: Swim | M35: 45328.806 | N35: 7
A36: =row()-1 -> 35 | B36: {=INDEX(users!$A:$A, RANDBETWEEN(1, COUNTA(users!$A:$A)))} -> 754 | C36: 1.502 | D36: 2.3 | G36: 1383.4 | H36: 0.022858796 | I36: 0.010659722 | J36: 3 | K36: 39 | L36: Run | M36: 45329.73 | N36: 2
A37: =row()-1 -> 36 | B37: {=INDEX(users!$A:$A, RANDBETWEEN(1, COUNTA(users!$A:$A)))} -> 475 | C37: 2.218 | D37: 4.2 | G37: 6129.6 | H37: 0.033854167 | I37: 0.031990741 | J37: 10 | K37: 30.4 | L37: Run | M37: 45330.793 | N37: 0
A38: =row()-1 -> 37 | B38: {=INDEX(users!$A:$A, RANDBETWEEN(1, COUNTA(users!$A:$A)))} -> 518 | C38: 0.6 | D38: 2.3 | G38: 1475 | H38: 0.029537037 | I38: 0.0284375 | J38: 0 | L38: Swim | M38: 45332.836 | N38: 9
A39: =row()-1 -> 38 | B39: {=INDEX(users!$A:$A, RANDBETWEEN(1, COUNTA(users!$A:$A)))} -> 988 | C39: 2.735 | D39: 5.5 | G39: 4985.4 | H39: 0.039513889 | I39: 0.021099537 | J39: 93 | K39: 23.4 | L39: Run | M39: 45333.438 | N39: 0
A40: =row()-1 -> 39 | B40: {=INDEX(users!$A:$A, RANDBETWEEN(1, COUNTA(users!$A:$A)))} -> 420 | C40: 2.445 | D40: 3.7 | G40: 6940.2 | H40: 0.044988426 | I40: 0.032847222 | J40: 260 | K40: 1626 | L40: Run | M40: 45336.633 | N40: 0
...

Sheet mcu_records
A1: mcu_id | B1: user_id | C1: height | D1: weight | E1: blood_pleasure | F1: cholesterol | G1: gluc | H1: BMI | I1: BMICat
A2: =IF(ROW()-1>1959,"",ROW()-1) -> 1 | B2: 1106 | C2: 168 | D2: 62 | E2: 110 | F2: 1 | G2: 1 | H2: 22 | I2: Normal
A3: =IF(ROW()-1>1959,"",ROW()-1) -> 2 | B3: 1440 | C3: 156 | D3: 85 | E3: 140 | F3: 3 | G3: 1 | H3: 34.9 | I3: Obese
A4: =IF(ROW()-1>1959,"",ROW()-1) -> 3 | B4: 385 | C4: 165 | D4: 64 | E4: 130 | F4: 3 | G4: 1 | H4: 23.5 | I4: Normal
A5: =IF(ROW()-1>1959,"",ROW()-1) -> 4 | B5: 1075 | C5: 169 | D5: 82 | E5: 150 | F5: 1 | G5: 1 | H5: 28.7 | I5: Over Weight
A6: =IF(ROW()-1>1959,"",ROW()-1) -> 5 | B6: 1224 | C6: 156 | D6: 56 | E6: 100 | F6: 1 | G6: 1 | H6: 23 | I6: Normal
A7: =IF(ROW()-1>1959,"",ROW()-1) -> 6 | B7: 1498 | C7: 151 | D7: 67 | E7: 120 | F7: 2 | G7: 2 | H7: 29.4 | I7: Over Weight
A8: =IF(ROW()-1>1959,"",ROW()-1) -> 7 | B8: 1667 | C8: 157 | D8: 93 | E8: 130 | F8: 3 | G8: 1 | H8: 37.7 | I8: Obese
A9: =IF(ROW()-1>1959,"",ROW()-1) -> 8 | B9: 533 | C9: 178 | D9: 95 | E9: 130 | F9: 3 | G9: 3 | H9: 30 | I9: Obese
A10: =IF(ROW()-1>1959,"",ROW()-1) -> 9 | B10: 962 | C10: 158 | D10: 71 | E10: 110 | F10: 1 | G10: 1 | H10: 28.4 | I10: Over Weight
A11: =IF(ROW()-1>1959,"",ROW()-1) -> 10 | B11: 1054 | C11: 164 | D11: 68 | E11: 110 | F11: 1 | G11: 1 | H11: 25.3 | I11: Over Weight
A12: =IF(ROW()-1>1959,"",ROW()-1) -> 11 | B12: 1727 | C12: 169 | D12: 80 | E12: 120 | F12: 1 | G12: 1 | H12: 28 | I12: Over Weight
A13: =IF(ROW()-1>1959,"",ROW()-1) -> 12 | B13: 1801 | C13: 173 | D13: 60 | E13: 120 | F13: 1 | G13: 1 | H13: 20 | I13: Normal
... A1960: =IF(ROW()-1>1959,"",ROW()-1) -> 1959 | B1960: 52 | C1960: 158 | D1960: 66 | E1960: 120 | F1960: 3 | G1960: 1 | H1960: 26.4 | I1960: Over Weight
